<?xml version="1.0"?>
<robot xmlns:xacro="http://www.ros.org/wiki/xacro">


  
  <!-- ________BASE LINK___________-->

  <link name="base_link">

  </link>

  <joint name="base_to_chassis" type="fixed">
    <origin xyz="0 0 0" rpy="-3.1415 0 0"/>
    <parent link="base_link"/>
    <child link="chassis_link"/>
  </joint>



  <!-- _____________CHASSIS LINK_____________-->
  <link name="chassis_link">

    <visual>
      <origin xyz="0 0 0" rpy="0 0 0"/>
      <geometry>
        <mesh filename="file:$(find kridtbot)/meshes/base_link.STL"/>
      </geometry>
    </visual>

  </link> 

  <joint name="chassis_to_diff" type="fixed">
    <origin xyz="-0.00062572 0.016893 -0.01406" rpy="1.5708 0 -1.5708"/>
    <parent link="chassis_link"/>
    <child link="diff_link"/>
  </joint>



  <!-- _____________DIFF LINK____________-->
  <link name="diff_link">

    <visual>
      <origin xyz="0 0 0" rpy="0 0 0"/>
      <geometry>
        <mesh filename="file:$(find kridtbot)/meshes/diff_link.STL"/>
      </geometry>
    </visual>
  
  </link>

  <joint name="diff_to_left_diff" type="revolute">
    <origin xyz="0 0 -0.28" rpy="-3.1416 0 -3.1416"/>
    <limit>
      effort="1000" lower="-1.5708" upper="1.5708" velocity="0.5"
    </limit>
    <parent link="diff_link"/>
    <child link="left_diff_link"/>
  </joint>
  <!-- _____________LEFT DIFF LINK____________-->
  <link name="left_diff_link">

    <visual>
      <origin xyz="0 0 0" rpy="0 0 0"/>
      <geometry>
        <mesh filename="file:$(find kridtbot)/meshes/left_diff_link.STL"/>
      </geometry>
    </visual>
  
  </link>
</robot>